2025-04-19 08:37:25,045 - financial_prediction_system - INFO - Financial Prediction API starting up
2025-04-19 08:47:34,307 - financial_prediction_system - INFO - Financial Prediction API shutting down
2025-04-19 08:47:36,578 - financial_prediction_system - INFO - Financial Prediction API starting up
2025-04-19 09:15:49,307 - financial_prediction_system - INFO - Financial Prediction API shutting down
2025-04-19 09:15:51,729 - financial_prediction_system - INFO - Financial Prediction API starting up
2025-04-19 09:15:55,134 - financial_prediction_system - INFO - Financial Prediction API shutting down
2025-04-19 09:15:57,408 - financial_prediction_system - INFO - Financial Prediction API starting up
2025-04-19 09:16:43,537 - financial_prediction_system - ERROR - Unhandled exception: Object of type Scatter is not JSON serializable
Traceback (most recent call last):
  File "/home/dj/projects/current/refined_yn/venv/lib/python3.12/site-packages/starlette/middleware/errors.py", line 165, in __call__
    await self.app(scope, receive, _send)
  File "/home/dj/projects/current/refined_yn/venv/lib/python3.12/site-packages/starlette/middleware/cors.py", line 85, in __call__
    await self.app(scope, receive, send)
  File "/home/dj/projects/current/refined_yn/venv/lib/python3.12/site-packages/starlette/middleware/exceptions.py", line 62, in __call__
    await wrap_app_handling_exceptions(self.app, conn)(scope, receive, send)
  File "/home/dj/projects/current/refined_yn/venv/lib/python3.12/site-packages/starlette/_exception_handler.py", line 53, in wrapped_app
    raise exc
  File "/home/dj/projects/current/refined_yn/venv/lib/python3.12/site-packages/starlette/_exception_handler.py", line 42, in wrapped_app
    await app(scope, receive, sender)
  File "/home/dj/projects/current/refined_yn/venv/lib/python3.12/site-packages/starlette/routing.py", line 714, in __call__
    await self.middleware_stack(scope, receive, send)
  File "/home/dj/projects/current/refined_yn/venv/lib/python3.12/site-packages/starlette/routing.py", line 734, in app
    await route.handle(scope, receive, send)
  File "/home/dj/projects/current/refined_yn/venv/lib/python3.12/site-packages/starlette/routing.py", line 288, in handle
    await self.app(scope, receive, send)
  File "/home/dj/projects/current/refined_yn/venv/lib/python3.12/site-packages/starlette/routing.py", line 76, in app
    await wrap_app_handling_exceptions(app, request)(scope, receive, send)
  File "/home/dj/projects/current/refined_yn/venv/lib/python3.12/site-packages/starlette/_exception_handler.py", line 53, in wrapped_app
    raise exc
  File "/home/dj/projects/current/refined_yn/venv/lib/python3.12/site-packages/starlette/_exception_handler.py", line 42, in wrapped_app
    await app(scope, receive, sender)
  File "/home/dj/projects/current/refined_yn/venv/lib/python3.12/site-packages/starlette/routing.py", line 73, in app
    response = await f(request)
               ^^^^^^^^^^^^^^^^
  File "/home/dj/projects/current/refined_yn/venv/lib/python3.12/site-packages/fastapi/routing.py", line 301, in app
    raw_response = await run_endpoint_function(
                   ^^^^^^^^^^^^^^^^^^^^^^^^^^^^
  File "/home/dj/projects/current/refined_yn/venv/lib/python3.12/site-packages/fastapi/routing.py", line 214, in run_endpoint_function
    return await run_in_threadpool(dependant.call, **values)
           ^^^^^^^^^^^^^^^^^^^^^^^^^^^^^^^^^^^^^^^^^^^^^^^^^
  File "/home/dj/projects/current/refined_yn/venv/lib/python3.12/site-packages/starlette/concurrency.py", line 37, in run_in_threadpool
    return await anyio.to_thread.run_sync(func)
           ^^^^^^^^^^^^^^^^^^^^^^^^^^^^^^^^^^^^
  File "/home/dj/projects/current/refined_yn/venv/lib/python3.12/site-packages/anyio/to_thread.py", line 56, in run_sync
    return await get_async_backend().run_sync_in_worker_thread(
           ^^^^^^^^^^^^^^^^^^^^^^^^^^^^^^^^^^^^^^^^^^^^^^^^^^^^
  File "/home/dj/projects/current/refined_yn/venv/lib/python3.12/site-packages/anyio/_backends/_asyncio.py", line 2470, in run_sync_in_worker_thread
    return await future
           ^^^^^^^^^^^^
  File "/home/dj/projects/current/refined_yn/venv/lib/python3.12/site-packages/anyio/_backends/_asyncio.py", line 967, in run
    result = context.run(func, *args)
             ^^^^^^^^^^^^^^^^^^^^^^^^
  File "/home/dj/projects/current/refined_yn/financial_prediction_system/api/routes/eda.py", line 62, in eda_endpoint
    return JSONResponse(content={
           ^^^^^^^^^^^^^^^^^^^^^^
  File "/home/dj/projects/current/refined_yn/venv/lib/python3.12/site-packages/starlette/responses.py", line 182, in __init__
    super().__init__(content, status_code, headers, media_type, background)
  File "/home/dj/projects/current/refined_yn/venv/lib/python3.12/site-packages/starlette/responses.py", line 45, in __init__
    self.body = self.render(content)
                ^^^^^^^^^^^^^^^^^^^^
  File "/home/dj/projects/current/refined_yn/venv/lib/python3.12/site-packages/starlette/responses.py", line 185, in render
    return json.dumps(
           ^^^^^^^^^^^
  File "/usr/lib/python3.12/json/__init__.py", line 238, in dumps
    **kw).encode(obj)
          ^^^^^^^^^^^
  File "/usr/lib/python3.12/json/encoder.py", line 200, in encode
    chunks = self.iterencode(o, _one_shot=True)
             ^^^^^^^^^^^^^^^^^^^^^^^^^^^^^^^^^^
  File "/usr/lib/python3.12/json/encoder.py", line 258, in iterencode
    return _iterencode(o, 0)
           ^^^^^^^^^^^^^^^^^
  File "/usr/lib/python3.12/json/encoder.py", line 180, in default
    raise TypeError(f'Object of type {o.__class__.__name__} '
TypeError: Object of type Scatter is not JSON serializable
2025-04-19 09:16:43,541 - financial_prediction_system - ERROR - Unhandled exception: Object of type Scatter is not JSON serializable
Traceback (most recent call last):
  File "/home/dj/projects/current/refined_yn/venv/lib/python3.12/site-packages/starlette/middleware/errors.py", line 165, in __call__
    await self.app(scope, receive, _send)
  File "/home/dj/projects/current/refined_yn/venv/lib/python3.12/site-packages/starlette/middleware/cors.py", line 85, in __call__
    await self.app(scope, receive, send)
  File "/home/dj/projects/current/refined_yn/venv/lib/python3.12/site-packages/starlette/middleware/exceptions.py", line 62, in __call__
    await wrap_app_handling_exceptions(self.app, conn)(scope, receive, send)
  File "/home/dj/projects/current/refined_yn/venv/lib/python3.12/site-packages/starlette/_exception_handler.py", line 53, in wrapped_app
    raise exc
  File "/home/dj/projects/current/refined_yn/venv/lib/python3.12/site-packages/starlette/_exception_handler.py", line 42, in wrapped_app
    await app(scope, receive, sender)
  File "/home/dj/projects/current/refined_yn/venv/lib/python3.12/site-packages/starlette/routing.py", line 714, in __call__
    await self.middleware_stack(scope, receive, send)
  File "/home/dj/projects/current/refined_yn/venv/lib/python3.12/site-packages/starlette/routing.py", line 734, in app
    await route.handle(scope, receive, send)
  File "/home/dj/projects/current/refined_yn/venv/lib/python3.12/site-packages/starlette/routing.py", line 288, in handle
    await self.app(scope, receive, send)
  File "/home/dj/projects/current/refined_yn/venv/lib/python3.12/site-packages/starlette/routing.py", line 76, in app
    await wrap_app_handling_exceptions(app, request)(scope, receive, send)
  File "/home/dj/projects/current/refined_yn/venv/lib/python3.12/site-packages/starlette/_exception_handler.py", line 53, in wrapped_app
    raise exc
  File "/home/dj/projects/current/refined_yn/venv/lib/python3.12/site-packages/starlette/_exception_handler.py", line 42, in wrapped_app
    await app(scope, receive, sender)
  File "/home/dj/projects/current/refined_yn/venv/lib/python3.12/site-packages/starlette/routing.py", line 73, in app
    response = await f(request)
               ^^^^^^^^^^^^^^^^
  File "/home/dj/projects/current/refined_yn/venv/lib/python3.12/site-packages/fastapi/routing.py", line 301, in app
    raw_response = await run_endpoint_function(
                   ^^^^^^^^^^^^^^^^^^^^^^^^^^^^
  File "/home/dj/projects/current/refined_yn/venv/lib/python3.12/site-packages/fastapi/routing.py", line 214, in run_endpoint_function
    return await run_in_threadpool(dependant.call, **values)
           ^^^^^^^^^^^^^^^^^^^^^^^^^^^^^^^^^^^^^^^^^^^^^^^^^
  File "/home/dj/projects/current/refined_yn/venv/lib/python3.12/site-packages/starlette/concurrency.py", line 37, in run_in_threadpool
    return await anyio.to_thread.run_sync(func)
           ^^^^^^^^^^^^^^^^^^^^^^^^^^^^^^^^^^^^
  File "/home/dj/projects/current/refined_yn/venv/lib/python3.12/site-packages/anyio/to_thread.py", line 56, in run_sync
    return await get_async_backend().run_sync_in_worker_thread(
           ^^^^^^^^^^^^^^^^^^^^^^^^^^^^^^^^^^^^^^^^^^^^^^^^^^^^
  File "/home/dj/projects/current/refined_yn/venv/lib/python3.12/site-packages/anyio/_backends/_asyncio.py", line 2470, in run_sync_in_worker_thread
    return await future
           ^^^^^^^^^^^^
  File "/home/dj/projects/current/refined_yn/venv/lib/python3.12/site-packages/anyio/_backends/_asyncio.py", line 967, in run
    result = context.run(func, *args)
             ^^^^^^^^^^^^^^^^^^^^^^^^
  File "/home/dj/projects/current/refined_yn/financial_prediction_system/api/routes/eda.py", line 62, in eda_endpoint
    return JSONResponse(content={
           ^^^^^^^^^^^^^^^^^^^^^^
  File "/home/dj/projects/current/refined_yn/venv/lib/python3.12/site-packages/starlette/responses.py", line 182, in __init__
    super().__init__(content, status_code, headers, media_type, background)
  File "/home/dj/projects/current/refined_yn/venv/lib/python3.12/site-packages/starlette/responses.py", line 45, in __init__
    self.body = self.render(content)
                ^^^^^^^^^^^^^^^^^^^^
  File "/home/dj/projects/current/refined_yn/venv/lib/python3.12/site-packages/starlette/responses.py", line 185, in render
    return json.dumps(
           ^^^^^^^^^^^
  File "/usr/lib/python3.12/json/__init__.py", line 238, in dumps
    **kw).encode(obj)
          ^^^^^^^^^^^
  File "/usr/lib/python3.12/json/encoder.py", line 200, in encode
    chunks = self.iterencode(o, _one_shot=True)
             ^^^^^^^^^^^^^^^^^^^^^^^^^^^^^^^^^^
  File "/usr/lib/python3.12/json/encoder.py", line 258, in iterencode
    return _iterencode(o, 0)
           ^^^^^^^^^^^^^^^^^
  File "/usr/lib/python3.12/json/encoder.py", line 180, in default
    raise TypeError(f'Object of type {o.__class__.__name__} '
TypeError: Object of type Scatter is not JSON serializable
2025-04-19 09:17:04,889 - financial_prediction_system - ERROR - Unhandled exception: Object of type Scatter is not JSON serializable
Traceback (most recent call last):
  File "/home/dj/projects/current/refined_yn/venv/lib/python3.12/site-packages/starlette/middleware/errors.py", line 165, in __call__
    await self.app(scope, receive, _send)
  File "/home/dj/projects/current/refined_yn/venv/lib/python3.12/site-packages/starlette/middleware/cors.py", line 85, in __call__
    await self.app(scope, receive, send)
  File "/home/dj/projects/current/refined_yn/venv/lib/python3.12/site-packages/starlette/middleware/exceptions.py", line 62, in __call__
    await wrap_app_handling_exceptions(self.app, conn)(scope, receive, send)
  File "/home/dj/projects/current/refined_yn/venv/lib/python3.12/site-packages/starlette/_exception_handler.py", line 53, in wrapped_app
    raise exc
  File "/home/dj/projects/current/refined_yn/venv/lib/python3.12/site-packages/starlette/_exception_handler.py", line 42, in wrapped_app
    await app(scope, receive, sender)
  File "/home/dj/projects/current/refined_yn/venv/lib/python3.12/site-packages/starlette/routing.py", line 714, in __call__
    await self.middleware_stack(scope, receive, send)
  File "/home/dj/projects/current/refined_yn/venv/lib/python3.12/site-packages/starlette/routing.py", line 734, in app
    await route.handle(scope, receive, send)
  File "/home/dj/projects/current/refined_yn/venv/lib/python3.12/site-packages/starlette/routing.py", line 288, in handle
    await self.app(scope, receive, send)
  File "/home/dj/projects/current/refined_yn/venv/lib/python3.12/site-packages/starlette/routing.py", line 76, in app
    await wrap_app_handling_exceptions(app, request)(scope, receive, send)
  File "/home/dj/projects/current/refined_yn/venv/lib/python3.12/site-packages/starlette/_exception_handler.py", line 53, in wrapped_app
    raise exc
  File "/home/dj/projects/current/refined_yn/venv/lib/python3.12/site-packages/starlette/_exception_handler.py", line 42, in wrapped_app
    await app(scope, receive, sender)
  File "/home/dj/projects/current/refined_yn/venv/lib/python3.12/site-packages/starlette/routing.py", line 73, in app
    response = await f(request)
               ^^^^^^^^^^^^^^^^
  File "/home/dj/projects/current/refined_yn/venv/lib/python3.12/site-packages/fastapi/routing.py", line 301, in app
    raw_response = await run_endpoint_function(
                   ^^^^^^^^^^^^^^^^^^^^^^^^^^^^
  File "/home/dj/projects/current/refined_yn/venv/lib/python3.12/site-packages/fastapi/routing.py", line 214, in run_endpoint_function
    return await run_in_threadpool(dependant.call, **values)
           ^^^^^^^^^^^^^^^^^^^^^^^^^^^^^^^^^^^^^^^^^^^^^^^^^
  File "/home/dj/projects/current/refined_yn/venv/lib/python3.12/site-packages/starlette/concurrency.py", line 37, in run_in_threadpool
    return await anyio.to_thread.run_sync(func)
           ^^^^^^^^^^^^^^^^^^^^^^^^^^^^^^^^^^^^
  File "/home/dj/projects/current/refined_yn/venv/lib/python3.12/site-packages/anyio/to_thread.py", line 56, in run_sync
    return await get_async_backend().run_sync_in_worker_thread(
           ^^^^^^^^^^^^^^^^^^^^^^^^^^^^^^^^^^^^^^^^^^^^^^^^^^^^
  File "/home/dj/projects/current/refined_yn/venv/lib/python3.12/site-packages/anyio/_backends/_asyncio.py", line 2470, in run_sync_in_worker_thread
    return await future
           ^^^^^^^^^^^^
  File "/home/dj/projects/current/refined_yn/venv/lib/python3.12/site-packages/anyio/_backends/_asyncio.py", line 967, in run
    result = context.run(func, *args)
             ^^^^^^^^^^^^^^^^^^^^^^^^
  File "/home/dj/projects/current/refined_yn/financial_prediction_system/api/routes/eda.py", line 62, in eda_endpoint
    return JSONResponse(content={
           ^^^^^^^^^^^^^^^^^^^^^^
  File "/home/dj/projects/current/refined_yn/venv/lib/python3.12/site-packages/starlette/responses.py", line 182, in __init__
    super().__init__(content, status_code, headers, media_type, background)
  File "/home/dj/projects/current/refined_yn/venv/lib/python3.12/site-packages/starlette/responses.py", line 45, in __init__
    self.body = self.render(content)
                ^^^^^^^^^^^^^^^^^^^^
  File "/home/dj/projects/current/refined_yn/venv/lib/python3.12/site-packages/starlette/responses.py", line 185, in render
    return json.dumps(
           ^^^^^^^^^^^
  File "/usr/lib/python3.12/json/__init__.py", line 238, in dumps
    **kw).encode(obj)
          ^^^^^^^^^^^
  File "/usr/lib/python3.12/json/encoder.py", line 200, in encode
    chunks = self.iterencode(o, _one_shot=True)
             ^^^^^^^^^^^^^^^^^^^^^^^^^^^^^^^^^^
  File "/usr/lib/python3.12/json/encoder.py", line 258, in iterencode
    return _iterencode(o, 0)
           ^^^^^^^^^^^^^^^^^
  File "/usr/lib/python3.12/json/encoder.py", line 180, in default
    raise TypeError(f'Object of type {o.__class__.__name__} '
TypeError: Object of type Scatter is not JSON serializable
2025-04-19 09:17:04,896 - financial_prediction_system - ERROR - Unhandled exception: Object of type Scatter is not JSON serializable
Traceback (most recent call last):
  File "/home/dj/projects/current/refined_yn/venv/lib/python3.12/site-packages/starlette/middleware/errors.py", line 165, in __call__
    await self.app(scope, receive, _send)
  File "/home/dj/projects/current/refined_yn/venv/lib/python3.12/site-packages/starlette/middleware/cors.py", line 85, in __call__
    await self.app(scope, receive, send)
  File "/home/dj/projects/current/refined_yn/venv/lib/python3.12/site-packages/starlette/middleware/exceptions.py", line 62, in __call__
    await wrap_app_handling_exceptions(self.app, conn)(scope, receive, send)
  File "/home/dj/projects/current/refined_yn/venv/lib/python3.12/site-packages/starlette/_exception_handler.py", line 53, in wrapped_app
    raise exc
  File "/home/dj/projects/current/refined_yn/venv/lib/python3.12/site-packages/starlette/_exception_handler.py", line 42, in wrapped_app
    await app(scope, receive, sender)
  File "/home/dj/projects/current/refined_yn/venv/lib/python3.12/site-packages/starlette/routing.py", line 714, in __call__
    await self.middleware_stack(scope, receive, send)
  File "/home/dj/projects/current/refined_yn/venv/lib/python3.12/site-packages/starlette/routing.py", line 734, in app
    await route.handle(scope, receive, send)
  File "/home/dj/projects/current/refined_yn/venv/lib/python3.12/site-packages/starlette/routing.py", line 288, in handle
    await self.app(scope, receive, send)
  File "/home/dj/projects/current/refined_yn/venv/lib/python3.12/site-packages/starlette/routing.py", line 76, in app
    await wrap_app_handling_exceptions(app, request)(scope, receive, send)
  File "/home/dj/projects/current/refined_yn/venv/lib/python3.12/site-packages/starlette/_exception_handler.py", line 53, in wrapped_app
    raise exc
  File "/home/dj/projects/current/refined_yn/venv/lib/python3.12/site-packages/starlette/_exception_handler.py", line 42, in wrapped_app
    await app(scope, receive, sender)
  File "/home/dj/projects/current/refined_yn/venv/lib/python3.12/site-packages/starlette/routing.py", line 73, in app
    response = await f(request)
               ^^^^^^^^^^^^^^^^
  File "/home/dj/projects/current/refined_yn/venv/lib/python3.12/site-packages/fastapi/routing.py", line 301, in app
    raw_response = await run_endpoint_function(
                   ^^^^^^^^^^^^^^^^^^^^^^^^^^^^
  File "/home/dj/projects/current/refined_yn/venv/lib/python3.12/site-packages/fastapi/routing.py", line 214, in run_endpoint_function
    return await run_in_threadpool(dependant.call, **values)
           ^^^^^^^^^^^^^^^^^^^^^^^^^^^^^^^^^^^^^^^^^^^^^^^^^
  File "/home/dj/projects/current/refined_yn/venv/lib/python3.12/site-packages/starlette/concurrency.py", line 37, in run_in_threadpool
    return await anyio.to_thread.run_sync(func)
           ^^^^^^^^^^^^^^^^^^^^^^^^^^^^^^^^^^^^
  File "/home/dj/projects/current/refined_yn/venv/lib/python3.12/site-packages/anyio/to_thread.py", line 56, in run_sync
    return await get_async_backend().run_sync_in_worker_thread(
           ^^^^^^^^^^^^^^^^^^^^^^^^^^^^^^^^^^^^^^^^^^^^^^^^^^^^
  File "/home/dj/projects/current/refined_yn/venv/lib/python3.12/site-packages/anyio/_backends/_asyncio.py", line 2470, in run_sync_in_worker_thread
    return await future
           ^^^^^^^^^^^^
  File "/home/dj/projects/current/refined_yn/venv/lib/python3.12/site-packages/anyio/_backends/_asyncio.py", line 967, in run
    result = context.run(func, *args)
             ^^^^^^^^^^^^^^^^^^^^^^^^
  File "/home/dj/projects/current/refined_yn/financial_prediction_system/api/routes/eda.py", line 62, in eda_endpoint
    return JSONResponse(content={
           ^^^^^^^^^^^^^^^^^^^^^^
  File "/home/dj/projects/current/refined_yn/venv/lib/python3.12/site-packages/starlette/responses.py", line 182, in __init__
    super().__init__(content, status_code, headers, media_type, background)
  File "/home/dj/projects/current/refined_yn/venv/lib/python3.12/site-packages/starlette/responses.py", line 45, in __init__
    self.body = self.render(content)
                ^^^^^^^^^^^^^^^^^^^^
  File "/home/dj/projects/current/refined_yn/venv/lib/python3.12/site-packages/starlette/responses.py", line 185, in render
    return json.dumps(
           ^^^^^^^^^^^
  File "/usr/lib/python3.12/json/__init__.py", line 238, in dumps
    **kw).encode(obj)
          ^^^^^^^^^^^
  File "/usr/lib/python3.12/json/encoder.py", line 200, in encode
    chunks = self.iterencode(o, _one_shot=True)
             ^^^^^^^^^^^^^^^^^^^^^^^^^^^^^^^^^^
  File "/usr/lib/python3.12/json/encoder.py", line 258, in iterencode
    return _iterencode(o, 0)
           ^^^^^^^^^^^^^^^^^
  File "/usr/lib/python3.12/json/encoder.py", line 180, in default
    raise TypeError(f'Object of type {o.__class__.__name__} '
TypeError: Object of type Scatter is not JSON serializable
2025-04-19 09:17:12,603 - financial_prediction_system - ERROR - Unhandled exception: Object of type Scatter is not JSON serializable
Traceback (most recent call last):
  File "/home/dj/projects/current/refined_yn/venv/lib/python3.12/site-packages/starlette/middleware/errors.py", line 165, in __call__
    await self.app(scope, receive, _send)
  File "/home/dj/projects/current/refined_yn/venv/lib/python3.12/site-packages/starlette/middleware/cors.py", line 85, in __call__
    await self.app(scope, receive, send)
  File "/home/dj/projects/current/refined_yn/venv/lib/python3.12/site-packages/starlette/middleware/exceptions.py", line 62, in __call__
    await wrap_app_handling_exceptions(self.app, conn)(scope, receive, send)
  File "/home/dj/projects/current/refined_yn/venv/lib/python3.12/site-packages/starlette/_exception_handler.py", line 53, in wrapped_app
    raise exc
  File "/home/dj/projects/current/refined_yn/venv/lib/python3.12/site-packages/starlette/_exception_handler.py", line 42, in wrapped_app
    await app(scope, receive, sender)
  File "/home/dj/projects/current/refined_yn/venv/lib/python3.12/site-packages/starlette/routing.py", line 714, in __call__
    await self.middleware_stack(scope, receive, send)
  File "/home/dj/projects/current/refined_yn/venv/lib/python3.12/site-packages/starlette/routing.py", line 734, in app
    await route.handle(scope, receive, send)
  File "/home/dj/projects/current/refined_yn/venv/lib/python3.12/site-packages/starlette/routing.py", line 288, in handle
    await self.app(scope, receive, send)
  File "/home/dj/projects/current/refined_yn/venv/lib/python3.12/site-packages/starlette/routing.py", line 76, in app
    await wrap_app_handling_exceptions(app, request)(scope, receive, send)
  File "/home/dj/projects/current/refined_yn/venv/lib/python3.12/site-packages/starlette/_exception_handler.py", line 53, in wrapped_app
    raise exc
  File "/home/dj/projects/current/refined_yn/venv/lib/python3.12/site-packages/starlette/_exception_handler.py", line 42, in wrapped_app
    await app(scope, receive, sender)
  File "/home/dj/projects/current/refined_yn/venv/lib/python3.12/site-packages/starlette/routing.py", line 73, in app
    response = await f(request)
               ^^^^^^^^^^^^^^^^
  File "/home/dj/projects/current/refined_yn/venv/lib/python3.12/site-packages/fastapi/routing.py", line 301, in app
    raw_response = await run_endpoint_function(
                   ^^^^^^^^^^^^^^^^^^^^^^^^^^^^
  File "/home/dj/projects/current/refined_yn/venv/lib/python3.12/site-packages/fastapi/routing.py", line 214, in run_endpoint_function
    return await run_in_threadpool(dependant.call, **values)
           ^^^^^^^^^^^^^^^^^^^^^^^^^^^^^^^^^^^^^^^^^^^^^^^^^
  File "/home/dj/projects/current/refined_yn/venv/lib/python3.12/site-packages/starlette/concurrency.py", line 37, in run_in_threadpool
    return await anyio.to_thread.run_sync(func)
           ^^^^^^^^^^^^^^^^^^^^^^^^^^^^^^^^^^^^
  File "/home/dj/projects/current/refined_yn/venv/lib/python3.12/site-packages/anyio/to_thread.py", line 56, in run_sync
    return await get_async_backend().run_sync_in_worker_thread(
           ^^^^^^^^^^^^^^^^^^^^^^^^^^^^^^^^^^^^^^^^^^^^^^^^^^^^
  File "/home/dj/projects/current/refined_yn/venv/lib/python3.12/site-packages/anyio/_backends/_asyncio.py", line 2470, in run_sync_in_worker_thread
    return await future
           ^^^^^^^^^^^^
  File "/home/dj/projects/current/refined_yn/venv/lib/python3.12/site-packages/anyio/_backends/_asyncio.py", line 967, in run
    result = context.run(func, *args)
             ^^^^^^^^^^^^^^^^^^^^^^^^
  File "/home/dj/projects/current/refined_yn/financial_prediction_system/api/routes/eda.py", line 62, in eda_endpoint
    return JSONResponse(content={
           ^^^^^^^^^^^^^^^^^^^^^^
  File "/home/dj/projects/current/refined_yn/venv/lib/python3.12/site-packages/starlette/responses.py", line 182, in __init__
    super().__init__(content, status_code, headers, media_type, background)
  File "/home/dj/projects/current/refined_yn/venv/lib/python3.12/site-packages/starlette/responses.py", line 45, in __init__
    self.body = self.render(content)
                ^^^^^^^^^^^^^^^^^^^^
  File "/home/dj/projects/current/refined_yn/venv/lib/python3.12/site-packages/starlette/responses.py", line 185, in render
    return json.dumps(
           ^^^^^^^^^^^
  File "/usr/lib/python3.12/json/__init__.py", line 238, in dumps
    **kw).encode(obj)
          ^^^^^^^^^^^
  File "/usr/lib/python3.12/json/encoder.py", line 200, in encode
    chunks = self.iterencode(o, _one_shot=True)
             ^^^^^^^^^^^^^^^^^^^^^^^^^^^^^^^^^^
  File "/usr/lib/python3.12/json/encoder.py", line 258, in iterencode
    return _iterencode(o, 0)
           ^^^^^^^^^^^^^^^^^
  File "/usr/lib/python3.12/json/encoder.py", line 180, in default
    raise TypeError(f'Object of type {o.__class__.__name__} '
TypeError: Object of type Scatter is not JSON serializable
2025-04-19 09:17:12,613 - financial_prediction_system - ERROR - Unhandled exception: Object of type Scatter is not JSON serializable
Traceback (most recent call last):
  File "/home/dj/projects/current/refined_yn/venv/lib/python3.12/site-packages/starlette/middleware/errors.py", line 165, in __call__
    await self.app(scope, receive, _send)
  File "/home/dj/projects/current/refined_yn/venv/lib/python3.12/site-packages/starlette/middleware/cors.py", line 85, in __call__
    await self.app(scope, receive, send)
  File "/home/dj/projects/current/refined_yn/venv/lib/python3.12/site-packages/starlette/middleware/exceptions.py", line 62, in __call__
    await wrap_app_handling_exceptions(self.app, conn)(scope, receive, send)
  File "/home/dj/projects/current/refined_yn/venv/lib/python3.12/site-packages/starlette/_exception_handler.py", line 53, in wrapped_app
    raise exc
  File "/home/dj/projects/current/refined_yn/venv/lib/python3.12/site-packages/starlette/_exception_handler.py", line 42, in wrapped_app
    await app(scope, receive, sender)
  File "/home/dj/projects/current/refined_yn/venv/lib/python3.12/site-packages/starlette/routing.py", line 714, in __call__
    await self.middleware_stack(scope, receive, send)
  File "/home/dj/projects/current/refined_yn/venv/lib/python3.12/site-packages/starlette/routing.py", line 734, in app
    await route.handle(scope, receive, send)
  File "/home/dj/projects/current/refined_yn/venv/lib/python3.12/site-packages/starlette/routing.py", line 288, in handle
    await self.app(scope, receive, send)
  File "/home/dj/projects/current/refined_yn/venv/lib/python3.12/site-packages/starlette/routing.py", line 76, in app
    await wrap_app_handling_exceptions(app, request)(scope, receive, send)
  File "/home/dj/projects/current/refined_yn/venv/lib/python3.12/site-packages/starlette/_exception_handler.py", line 53, in wrapped_app
    raise exc
  File "/home/dj/projects/current/refined_yn/venv/lib/python3.12/site-packages/starlette/_exception_handler.py", line 42, in wrapped_app
    await app(scope, receive, sender)
  File "/home/dj/projects/current/refined_yn/venv/lib/python3.12/site-packages/starlette/routing.py", line 73, in app
    response = await f(request)
               ^^^^^^^^^^^^^^^^
  File "/home/dj/projects/current/refined_yn/venv/lib/python3.12/site-packages/fastapi/routing.py", line 301, in app
    raw_response = await run_endpoint_function(
                   ^^^^^^^^^^^^^^^^^^^^^^^^^^^^
  File "/home/dj/projects/current/refined_yn/venv/lib/python3.12/site-packages/fastapi/routing.py", line 214, in run_endpoint_function
    return await run_in_threadpool(dependant.call, **values)
           ^^^^^^^^^^^^^^^^^^^^^^^^^^^^^^^^^^^^^^^^^^^^^^^^^
  File "/home/dj/projects/current/refined_yn/venv/lib/python3.12/site-packages/starlette/concurrency.py", line 37, in run_in_threadpool
    return await anyio.to_thread.run_sync(func)
           ^^^^^^^^^^^^^^^^^^^^^^^^^^^^^^^^^^^^
  File "/home/dj/projects/current/refined_yn/venv/lib/python3.12/site-packages/anyio/to_thread.py", line 56, in run_sync
    return await get_async_backend().run_sync_in_worker_thread(
           ^^^^^^^^^^^^^^^^^^^^^^^^^^^^^^^^^^^^^^^^^^^^^^^^^^^^
  File "/home/dj/projects/current/refined_yn/venv/lib/python3.12/site-packages/anyio/_backends/_asyncio.py", line 2470, in run_sync_in_worker_thread
    return await future
           ^^^^^^^^^^^^
  File "/home/dj/projects/current/refined_yn/venv/lib/python3.12/site-packages/anyio/_backends/_asyncio.py", line 967, in run
    result = context.run(func, *args)
             ^^^^^^^^^^^^^^^^^^^^^^^^
  File "/home/dj/projects/current/refined_yn/financial_prediction_system/api/routes/eda.py", line 62, in eda_endpoint
    return JSONResponse(content={
           ^^^^^^^^^^^^^^^^^^^^^^
  File "/home/dj/projects/current/refined_yn/venv/lib/python3.12/site-packages/starlette/responses.py", line 182, in __init__
    super().__init__(content, status_code, headers, media_type, background)
  File "/home/dj/projects/current/refined_yn/venv/lib/python3.12/site-packages/starlette/responses.py", line 45, in __init__
    self.body = self.render(content)
                ^^^^^^^^^^^^^^^^^^^^
  File "/home/dj/projects/current/refined_yn/venv/lib/python3.12/site-packages/starlette/responses.py", line 185, in render
    return json.dumps(
           ^^^^^^^^^^^
  File "/usr/lib/python3.12/json/__init__.py", line 238, in dumps
    **kw).encode(obj)
          ^^^^^^^^^^^
  File "/usr/lib/python3.12/json/encoder.py", line 200, in encode
    chunks = self.iterencode(o, _one_shot=True)
             ^^^^^^^^^^^^^^^^^^^^^^^^^^^^^^^^^^
  File "/usr/lib/python3.12/json/encoder.py", line 258, in iterencode
    return _iterencode(o, 0)
           ^^^^^^^^^^^^^^^^^
  File "/usr/lib/python3.12/json/encoder.py", line 180, in default
    raise TypeError(f'Object of type {o.__class__.__name__} '
TypeError: Object of type Scatter is not JSON serializable
2025-04-19 09:17:51,061 - financial_prediction_system - INFO - Financial Prediction API shutting down
2025-04-19 09:17:53,341 - financial_prediction_system - INFO - Financial Prediction API starting up
2025-04-19 09:18:19,325 - financial_prediction_system - ERROR - Unhandled exception: Object of type ndarray is not JSON serializable
Traceback (most recent call last):
  File "/home/dj/projects/current/refined_yn/venv/lib/python3.12/site-packages/starlette/middleware/errors.py", line 165, in __call__
    await self.app(scope, receive, _send)
  File "/home/dj/projects/current/refined_yn/venv/lib/python3.12/site-packages/starlette/middleware/cors.py", line 85, in __call__
    await self.app(scope, receive, send)
  File "/home/dj/projects/current/refined_yn/venv/lib/python3.12/site-packages/starlette/middleware/exceptions.py", line 62, in __call__
    await wrap_app_handling_exceptions(self.app, conn)(scope, receive, send)
  File "/home/dj/projects/current/refined_yn/venv/lib/python3.12/site-packages/starlette/_exception_handler.py", line 53, in wrapped_app
    raise exc
  File "/home/dj/projects/current/refined_yn/venv/lib/python3.12/site-packages/starlette/_exception_handler.py", line 42, in wrapped_app
    await app(scope, receive, sender)
  File "/home/dj/projects/current/refined_yn/venv/lib/python3.12/site-packages/starlette/routing.py", line 714, in __call__
    await self.middleware_stack(scope, receive, send)
  File "/home/dj/projects/current/refined_yn/venv/lib/python3.12/site-packages/starlette/routing.py", line 734, in app
    await route.handle(scope, receive, send)
  File "/home/dj/projects/current/refined_yn/venv/lib/python3.12/site-packages/starlette/routing.py", line 288, in handle
    await self.app(scope, receive, send)
  File "/home/dj/projects/current/refined_yn/venv/lib/python3.12/site-packages/starlette/routing.py", line 76, in app
    await wrap_app_handling_exceptions(app, request)(scope, receive, send)
  File "/home/dj/projects/current/refined_yn/venv/lib/python3.12/site-packages/starlette/_exception_handler.py", line 53, in wrapped_app
    raise exc
  File "/home/dj/projects/current/refined_yn/venv/lib/python3.12/site-packages/starlette/_exception_handler.py", line 42, in wrapped_app
    await app(scope, receive, sender)
  File "/home/dj/projects/current/refined_yn/venv/lib/python3.12/site-packages/starlette/routing.py", line 73, in app
    response = await f(request)
               ^^^^^^^^^^^^^^^^
  File "/home/dj/projects/current/refined_yn/venv/lib/python3.12/site-packages/fastapi/routing.py", line 301, in app
    raw_response = await run_endpoint_function(
                   ^^^^^^^^^^^^^^^^^^^^^^^^^^^^
  File "/home/dj/projects/current/refined_yn/venv/lib/python3.12/site-packages/fastapi/routing.py", line 214, in run_endpoint_function
    return await run_in_threadpool(dependant.call, **values)
           ^^^^^^^^^^^^^^^^^^^^^^^^^^^^^^^^^^^^^^^^^^^^^^^^^
  File "/home/dj/projects/current/refined_yn/venv/lib/python3.12/site-packages/starlette/concurrency.py", line 37, in run_in_threadpool
    return await anyio.to_thread.run_sync(func)
           ^^^^^^^^^^^^^^^^^^^^^^^^^^^^^^^^^^^^
  File "/home/dj/projects/current/refined_yn/venv/lib/python3.12/site-packages/anyio/to_thread.py", line 56, in run_sync
    return await get_async_backend().run_sync_in_worker_thread(
           ^^^^^^^^^^^^^^^^^^^^^^^^^^^^^^^^^^^^^^^^^^^^^^^^^^^^
  File "/home/dj/projects/current/refined_yn/venv/lib/python3.12/site-packages/anyio/_backends/_asyncio.py", line 2470, in run_sync_in_worker_thread
    return await future
           ^^^^^^^^^^^^
  File "/home/dj/projects/current/refined_yn/venv/lib/python3.12/site-packages/anyio/_backends/_asyncio.py", line 967, in run
    result = context.run(func, *args)
             ^^^^^^^^^^^^^^^^^^^^^^^^
  File "/home/dj/projects/current/refined_yn/financial_prediction_system/api/routes/eda.py", line 62, in eda_endpoint
    return JSONResponse(content={
           ^^^^^^^^^^^^^^^^^^^^^^
  File "/home/dj/projects/current/refined_yn/venv/lib/python3.12/site-packages/starlette/responses.py", line 182, in __init__
    super().__init__(content, status_code, headers, media_type, background)
  File "/home/dj/projects/current/refined_yn/venv/lib/python3.12/site-packages/starlette/responses.py", line 45, in __init__
    self.body = self.render(content)
                ^^^^^^^^^^^^^^^^^^^^
  File "/home/dj/projects/current/refined_yn/venv/lib/python3.12/site-packages/starlette/responses.py", line 185, in render
    return json.dumps(
           ^^^^^^^^^^^
  File "/usr/lib/python3.12/json/__init__.py", line 238, in dumps
    **kw).encode(obj)
          ^^^^^^^^^^^
  File "/usr/lib/python3.12/json/encoder.py", line 200, in encode
    chunks = self.iterencode(o, _one_shot=True)
             ^^^^^^^^^^^^^^^^^^^^^^^^^^^^^^^^^^
  File "/usr/lib/python3.12/json/encoder.py", line 258, in iterencode
    return _iterencode(o, 0)
           ^^^^^^^^^^^^^^^^^
  File "/usr/lib/python3.12/json/encoder.py", line 180, in default
    raise TypeError(f'Object of type {o.__class__.__name__} '
TypeError: Object of type ndarray is not JSON serializable
2025-04-19 09:18:19,335 - financial_prediction_system - ERROR - Unhandled exception: Object of type ndarray is not JSON serializable
Traceback (most recent call last):
  File "/home/dj/projects/current/refined_yn/venv/lib/python3.12/site-packages/starlette/middleware/errors.py", line 165, in __call__
    await self.app(scope, receive, _send)
  File "/home/dj/projects/current/refined_yn/venv/lib/python3.12/site-packages/starlette/middleware/cors.py", line 85, in __call__
    await self.app(scope, receive, send)
  File "/home/dj/projects/current/refined_yn/venv/lib/python3.12/site-packages/starlette/middleware/exceptions.py", line 62, in __call__
    await wrap_app_handling_exceptions(self.app, conn)(scope, receive, send)
  File "/home/dj/projects/current/refined_yn/venv/lib/python3.12/site-packages/starlette/_exception_handler.py", line 53, in wrapped_app
    raise exc
  File "/home/dj/projects/current/refined_yn/venv/lib/python3.12/site-packages/starlette/_exception_handler.py", line 42, in wrapped_app
    await app(scope, receive, sender)
  File "/home/dj/projects/current/refined_yn/venv/lib/python3.12/site-packages/starlette/routing.py", line 714, in __call__
    await self.middleware_stack(scope, receive, send)
  File "/home/dj/projects/current/refined_yn/venv/lib/python3.12/site-packages/starlette/routing.py", line 734, in app
    await route.handle(scope, receive, send)
  File "/home/dj/projects/current/refined_yn/venv/lib/python3.12/site-packages/starlette/routing.py", line 288, in handle
    await self.app(scope, receive, send)
  File "/home/dj/projects/current/refined_yn/venv/lib/python3.12/site-packages/starlette/routing.py", line 76, in app
    await wrap_app_handling_exceptions(app, request)(scope, receive, send)
  File "/home/dj/projects/current/refined_yn/venv/lib/python3.12/site-packages/starlette/_exception_handler.py", line 53, in wrapped_app
    raise exc
  File "/home/dj/projects/current/refined_yn/venv/lib/python3.12/site-packages/starlette/_exception_handler.py", line 42, in wrapped_app
    await app(scope, receive, sender)
  File "/home/dj/projects/current/refined_yn/venv/lib/python3.12/site-packages/starlette/routing.py", line 73, in app
    response = await f(request)
               ^^^^^^^^^^^^^^^^
  File "/home/dj/projects/current/refined_yn/venv/lib/python3.12/site-packages/fastapi/routing.py", line 301, in app
    raw_response = await run_endpoint_function(
                   ^^^^^^^^^^^^^^^^^^^^^^^^^^^^
  File "/home/dj/projects/current/refined_yn/venv/lib/python3.12/site-packages/fastapi/routing.py", line 214, in run_endpoint_function
    return await run_in_threadpool(dependant.call, **values)
           ^^^^^^^^^^^^^^^^^^^^^^^^^^^^^^^^^^^^^^^^^^^^^^^^^
  File "/home/dj/projects/current/refined_yn/venv/lib/python3.12/site-packages/starlette/concurrency.py", line 37, in run_in_threadpool
    return await anyio.to_thread.run_sync(func)
           ^^^^^^^^^^^^^^^^^^^^^^^^^^^^^^^^^^^^
  File "/home/dj/projects/current/refined_yn/venv/lib/python3.12/site-packages/anyio/to_thread.py", line 56, in run_sync
    return await get_async_backend().run_sync_in_worker_thread(
           ^^^^^^^^^^^^^^^^^^^^^^^^^^^^^^^^^^^^^^^^^^^^^^^^^^^^
  File "/home/dj/projects/current/refined_yn/venv/lib/python3.12/site-packages/anyio/_backends/_asyncio.py", line 2470, in run_sync_in_worker_thread
    return await future
           ^^^^^^^^^^^^
  File "/home/dj/projects/current/refined_yn/venv/lib/python3.12/site-packages/anyio/_backends/_asyncio.py", line 967, in run
    result = context.run(func, *args)
             ^^^^^^^^^^^^^^^^^^^^^^^^
  File "/home/dj/projects/current/refined_yn/financial_prediction_system/api/routes/eda.py", line 62, in eda_endpoint
    return JSONResponse(content={
           ^^^^^^^^^^^^^^^^^^^^^^
  File "/home/dj/projects/current/refined_yn/venv/lib/python3.12/site-packages/starlette/responses.py", line 182, in __init__
    super().__init__(content, status_code, headers, media_type, background)
  File "/home/dj/projects/current/refined_yn/venv/lib/python3.12/site-packages/starlette/responses.py", line 45, in __init__
    self.body = self.render(content)
                ^^^^^^^^^^^^^^^^^^^^
  File "/home/dj/projects/current/refined_yn/venv/lib/python3.12/site-packages/starlette/responses.py", line 185, in render
    return json.dumps(
           ^^^^^^^^^^^
  File "/usr/lib/python3.12/json/__init__.py", line 238, in dumps
    **kw).encode(obj)
          ^^^^^^^^^^^
  File "/usr/lib/python3.12/json/encoder.py", line 200, in encode
    chunks = self.iterencode(o, _one_shot=True)
             ^^^^^^^^^^^^^^^^^^^^^^^^^^^^^^^^^^
  File "/usr/lib/python3.12/json/encoder.py", line 258, in iterencode
    return _iterencode(o, 0)
           ^^^^^^^^^^^^^^^^^
  File "/usr/lib/python3.12/json/encoder.py", line 180, in default
    raise TypeError(f'Object of type {o.__class__.__name__} '
TypeError: Object of type ndarray is not JSON serializable
2025-04-19 09:18:38,400 - financial_prediction_system - INFO - Financial Prediction API shutting down
2025-04-19 09:18:42,334 - financial_prediction_system - INFO - Financial Prediction API starting up
2025-04-19 09:18:48,071 - financial_prediction_system - ERROR - Unhandled exception: Object of type ndarray is not JSON serializable
Traceback (most recent call last):
  File "/home/dj/projects/current/refined_yn/venv/lib/python3.12/site-packages/starlette/middleware/errors.py", line 165, in __call__
    await self.app(scope, receive, _send)
  File "/home/dj/projects/current/refined_yn/venv/lib/python3.12/site-packages/starlette/middleware/cors.py", line 85, in __call__
    await self.app(scope, receive, send)
  File "/home/dj/projects/current/refined_yn/venv/lib/python3.12/site-packages/starlette/middleware/exceptions.py", line 62, in __call__
    await wrap_app_handling_exceptions(self.app, conn)(scope, receive, send)
  File "/home/dj/projects/current/refined_yn/venv/lib/python3.12/site-packages/starlette/_exception_handler.py", line 53, in wrapped_app
    raise exc
  File "/home/dj/projects/current/refined_yn/venv/lib/python3.12/site-packages/starlette/_exception_handler.py", line 42, in wrapped_app
    await app(scope, receive, sender)
  File "/home/dj/projects/current/refined_yn/venv/lib/python3.12/site-packages/starlette/routing.py", line 714, in __call__
    await self.middleware_stack(scope, receive, send)
  File "/home/dj/projects/current/refined_yn/venv/lib/python3.12/site-packages/starlette/routing.py", line 734, in app
    await route.handle(scope, receive, send)
  File "/home/dj/projects/current/refined_yn/venv/lib/python3.12/site-packages/starlette/routing.py", line 288, in handle
    await self.app(scope, receive, send)
  File "/home/dj/projects/current/refined_yn/venv/lib/python3.12/site-packages/starlette/routing.py", line 76, in app
    await wrap_app_handling_exceptions(app, request)(scope, receive, send)
  File "/home/dj/projects/current/refined_yn/venv/lib/python3.12/site-packages/starlette/_exception_handler.py", line 53, in wrapped_app
    raise exc
  File "/home/dj/projects/current/refined_yn/venv/lib/python3.12/site-packages/starlette/_exception_handler.py", line 42, in wrapped_app
    await app(scope, receive, sender)
  File "/home/dj/projects/current/refined_yn/venv/lib/python3.12/site-packages/starlette/routing.py", line 73, in app
    response = await f(request)
               ^^^^^^^^^^^^^^^^
  File "/home/dj/projects/current/refined_yn/venv/lib/python3.12/site-packages/fastapi/routing.py", line 301, in app
    raw_response = await run_endpoint_function(
                   ^^^^^^^^^^^^^^^^^^^^^^^^^^^^
  File "/home/dj/projects/current/refined_yn/venv/lib/python3.12/site-packages/fastapi/routing.py", line 214, in run_endpoint_function
    return await run_in_threadpool(dependant.call, **values)
           ^^^^^^^^^^^^^^^^^^^^^^^^^^^^^^^^^^^^^^^^^^^^^^^^^
  File "/home/dj/projects/current/refined_yn/venv/lib/python3.12/site-packages/starlette/concurrency.py", line 37, in run_in_threadpool
    return await anyio.to_thread.run_sync(func)
           ^^^^^^^^^^^^^^^^^^^^^^^^^^^^^^^^^^^^
  File "/home/dj/projects/current/refined_yn/venv/lib/python3.12/site-packages/anyio/to_thread.py", line 56, in run_sync
    return await get_async_backend().run_sync_in_worker_thread(
           ^^^^^^^^^^^^^^^^^^^^^^^^^^^^^^^^^^^^^^^^^^^^^^^^^^^^
  File "/home/dj/projects/current/refined_yn/venv/lib/python3.12/site-packages/anyio/_backends/_asyncio.py", line 2470, in run_sync_in_worker_thread
    return await future
           ^^^^^^^^^^^^
  File "/home/dj/projects/current/refined_yn/venv/lib/python3.12/site-packages/anyio/_backends/_asyncio.py", line 967, in run
    result = context.run(func, *args)
             ^^^^^^^^^^^^^^^^^^^^^^^^
  File "/home/dj/projects/current/refined_yn/financial_prediction_system/api/routes/eda.py", line 62, in eda_endpoint
    return JSONResponse(content={
           ^^^^^^^^^^^^^^^^^^^^^^
  File "/home/dj/projects/current/refined_yn/venv/lib/python3.12/site-packages/starlette/responses.py", line 182, in __init__
    super().__init__(content, status_code, headers, media_type, background)
  File "/home/dj/projects/current/refined_yn/venv/lib/python3.12/site-packages/starlette/responses.py", line 45, in __init__
    self.body = self.render(content)
                ^^^^^^^^^^^^^^^^^^^^
  File "/home/dj/projects/current/refined_yn/venv/lib/python3.12/site-packages/starlette/responses.py", line 185, in render
    return json.dumps(
           ^^^^^^^^^^^
  File "/usr/lib/python3.12/json/__init__.py", line 238, in dumps
    **kw).encode(obj)
          ^^^^^^^^^^^
  File "/usr/lib/python3.12/json/encoder.py", line 200, in encode
    chunks = self.iterencode(o, _one_shot=True)
             ^^^^^^^^^^^^^^^^^^^^^^^^^^^^^^^^^^
  File "/usr/lib/python3.12/json/encoder.py", line 258, in iterencode
    return _iterencode(o, 0)
           ^^^^^^^^^^^^^^^^^
  File "/usr/lib/python3.12/json/encoder.py", line 180, in default
    raise TypeError(f'Object of type {o.__class__.__name__} '
TypeError: Object of type ndarray is not JSON serializable
2025-04-19 09:18:48,074 - financial_prediction_system - ERROR - Unhandled exception: Object of type ndarray is not JSON serializable
Traceback (most recent call last):
  File "/home/dj/projects/current/refined_yn/venv/lib/python3.12/site-packages/starlette/middleware/errors.py", line 165, in __call__
    await self.app(scope, receive, _send)
  File "/home/dj/projects/current/refined_yn/venv/lib/python3.12/site-packages/starlette/middleware/cors.py", line 85, in __call__
    await self.app(scope, receive, send)
  File "/home/dj/projects/current/refined_yn/venv/lib/python3.12/site-packages/starlette/middleware/exceptions.py", line 62, in __call__
    await wrap_app_handling_exceptions(self.app, conn)(scope, receive, send)
  File "/home/dj/projects/current/refined_yn/venv/lib/python3.12/site-packages/starlette/_exception_handler.py", line 53, in wrapped_app
    raise exc
  File "/home/dj/projects/current/refined_yn/venv/lib/python3.12/site-packages/starlette/_exception_handler.py", line 42, in wrapped_app
    await app(scope, receive, sender)
  File "/home/dj/projects/current/refined_yn/venv/lib/python3.12/site-packages/starlette/routing.py", line 714, in __call__
    await self.middleware_stack(scope, receive, send)
  File "/home/dj/projects/current/refined_yn/venv/lib/python3.12/site-packages/starlette/routing.py", line 734, in app
    await route.handle(scope, receive, send)
  File "/home/dj/projects/current/refined_yn/venv/lib/python3.12/site-packages/starlette/routing.py", line 288, in handle
    await self.app(scope, receive, send)
  File "/home/dj/projects/current/refined_yn/venv/lib/python3.12/site-packages/starlette/routing.py", line 76, in app
    await wrap_app_handling_exceptions(app, request)(scope, receive, send)
  File "/home/dj/projects/current/refined_yn/venv/lib/python3.12/site-packages/starlette/_exception_handler.py", line 53, in wrapped_app
    raise exc
  File "/home/dj/projects/current/refined_yn/venv/lib/python3.12/site-packages/starlette/_exception_handler.py", line 42, in wrapped_app
    await app(scope, receive, sender)
  File "/home/dj/projects/current/refined_yn/venv/lib/python3.12/site-packages/starlette/routing.py", line 73, in app
    response = await f(request)
               ^^^^^^^^^^^^^^^^
  File "/home/dj/projects/current/refined_yn/venv/lib/python3.12/site-packages/fastapi/routing.py", line 301, in app
    raw_response = await run_endpoint_function(
                   ^^^^^^^^^^^^^^^^^^^^^^^^^^^^
  File "/home/dj/projects/current/refined_yn/venv/lib/python3.12/site-packages/fastapi/routing.py", line 214, in run_endpoint_function
    return await run_in_threadpool(dependant.call, **values)
           ^^^^^^^^^^^^^^^^^^^^^^^^^^^^^^^^^^^^^^^^^^^^^^^^^
  File "/home/dj/projects/current/refined_yn/venv/lib/python3.12/site-packages/starlette/concurrency.py", line 37, in run_in_threadpool
    return await anyio.to_thread.run_sync(func)
           ^^^^^^^^^^^^^^^^^^^^^^^^^^^^^^^^^^^^
  File "/home/dj/projects/current/refined_yn/venv/lib/python3.12/site-packages/anyio/to_thread.py", line 56, in run_sync
    return await get_async_backend().run_sync_in_worker_thread(
           ^^^^^^^^^^^^^^^^^^^^^^^^^^^^^^^^^^^^^^^^^^^^^^^^^^^^
  File "/home/dj/projects/current/refined_yn/venv/lib/python3.12/site-packages/anyio/_backends/_asyncio.py", line 2470, in run_sync_in_worker_thread
    return await future
           ^^^^^^^^^^^^
  File "/home/dj/projects/current/refined_yn/venv/lib/python3.12/site-packages/anyio/_backends/_asyncio.py", line 967, in run
    result = context.run(func, *args)
             ^^^^^^^^^^^^^^^^^^^^^^^^
  File "/home/dj/projects/current/refined_yn/financial_prediction_system/api/routes/eda.py", line 62, in eda_endpoint
    return JSONResponse(content={
           ^^^^^^^^^^^^^^^^^^^^^^
  File "/home/dj/projects/current/refined_yn/venv/lib/python3.12/site-packages/starlette/responses.py", line 182, in __init__
    super().__init__(content, status_code, headers, media_type, background)
  File "/home/dj/projects/current/refined_yn/venv/lib/python3.12/site-packages/starlette/responses.py", line 45, in __init__
    self.body = self.render(content)
                ^^^^^^^^^^^^^^^^^^^^
  File "/home/dj/projects/current/refined_yn/venv/lib/python3.12/site-packages/starlette/responses.py", line 185, in render
    return json.dumps(
           ^^^^^^^^^^^
  File "/usr/lib/python3.12/json/__init__.py", line 238, in dumps
    **kw).encode(obj)
          ^^^^^^^^^^^
  File "/usr/lib/python3.12/json/encoder.py", line 200, in encode
    chunks = self.iterencode(o, _one_shot=True)
             ^^^^^^^^^^^^^^^^^^^^^^^^^^^^^^^^^^
  File "/usr/lib/python3.12/json/encoder.py", line 258, in iterencode
    return _iterencode(o, 0)
           ^^^^^^^^^^^^^^^^^
  File "/usr/lib/python3.12/json/encoder.py", line 180, in default
    raise TypeError(f'Object of type {o.__class__.__name__} '
TypeError: Object of type ndarray is not JSON serializable
2025-04-19 09:19:32,306 - financial_prediction_system - INFO - Financial Prediction API shutting down
2025-04-19 09:19:34,606 - financial_prediction_system - INFO - Financial Prediction API starting up
2025-04-19 09:36:57,462 - financial_prediction_system - INFO - Financial Prediction API shutting down
2025-04-19 09:36:59,769 - financial_prediction_system - INFO - Financial Prediction API starting up
2025-04-19 09:37:08,183 - financial_prediction_system - INFO - Financial Prediction API shutting down
2025-04-19 09:37:10,481 - financial_prediction_system - INFO - Financial Prediction API starting up
2025-04-19 09:37:46,860 - financial_prediction_system - ERROR - Unhandled exception: [TypeError('cannot convert dictionary update sequence element #0 to a sequence'), TypeError('vars() argument must have __dict__ attribute')]
Traceback (most recent call last):
  File "/home/dj/projects/current/refined_yn/venv/lib/python3.12/site-packages/fastapi/encoders.py", line 324, in jsonable_encoder
    data = dict(obj)
           ^^^^^^^^^
TypeError: cannot convert dictionary update sequence element #0 to a sequence

During handling of the above exception, another exception occurred:

Traceback (most recent call last):
  File "/home/dj/projects/current/refined_yn/venv/lib/python3.12/site-packages/fastapi/encoders.py", line 329, in jsonable_encoder
    data = vars(obj)
           ^^^^^^^^^
TypeError: vars() argument must have __dict__ attribute

The above exception was the direct cause of the following exception:

Traceback (most recent call last):
  File "/home/dj/projects/current/refined_yn/venv/lib/python3.12/site-packages/starlette/middleware/errors.py", line 165, in __call__
    await self.app(scope, receive, _send)
  File "/home/dj/projects/current/refined_yn/venv/lib/python3.12/site-packages/starlette/middleware/cors.py", line 85, in __call__
    await self.app(scope, receive, send)
  File "/home/dj/projects/current/refined_yn/venv/lib/python3.12/site-packages/starlette/middleware/exceptions.py", line 62, in __call__
    await wrap_app_handling_exceptions(self.app, conn)(scope, receive, send)
  File "/home/dj/projects/current/refined_yn/venv/lib/python3.12/site-packages/starlette/_exception_handler.py", line 53, in wrapped_app
    raise exc
  File "/home/dj/projects/current/refined_yn/venv/lib/python3.12/site-packages/starlette/_exception_handler.py", line 42, in wrapped_app
    await app(scope, receive, sender)
  File "/home/dj/projects/current/refined_yn/venv/lib/python3.12/site-packages/starlette/routing.py", line 714, in __call__
    await self.middleware_stack(scope, receive, send)
  File "/home/dj/projects/current/refined_yn/venv/lib/python3.12/site-packages/starlette/routing.py", line 734, in app
    await route.handle(scope, receive, send)
  File "/home/dj/projects/current/refined_yn/venv/lib/python3.12/site-packages/starlette/routing.py", line 288, in handle
    await self.app(scope, receive, send)
  File "/home/dj/projects/current/refined_yn/venv/lib/python3.12/site-packages/starlette/routing.py", line 76, in app
    await wrap_app_handling_exceptions(app, request)(scope, receive, send)
  File "/home/dj/projects/current/refined_yn/venv/lib/python3.12/site-packages/starlette/_exception_handler.py", line 53, in wrapped_app
    raise exc
  File "/home/dj/projects/current/refined_yn/venv/lib/python3.12/site-packages/starlette/_exception_handler.py", line 42, in wrapped_app
    await app(scope, receive, sender)
  File "/home/dj/projects/current/refined_yn/venv/lib/python3.12/site-packages/starlette/routing.py", line 73, in app
    response = await f(request)
               ^^^^^^^^^^^^^^^^
  File "/home/dj/projects/current/refined_yn/venv/lib/python3.12/site-packages/fastapi/routing.py", line 327, in app
    content = await serialize_response(
              ^^^^^^^^^^^^^^^^^^^^^^^^^
  File "/home/dj/projects/current/refined_yn/venv/lib/python3.12/site-packages/fastapi/routing.py", line 201, in serialize_response
    return jsonable_encoder(response_content)
           ^^^^^^^^^^^^^^^^^^^^^^^^^^^^^^^^^^
  File "/home/dj/projects/current/refined_yn/venv/lib/python3.12/site-packages/fastapi/encoders.py", line 289, in jsonable_encoder
    encoded_value = jsonable_encoder(
                    ^^^^^^^^^^^^^^^^^
  File "/home/dj/projects/current/refined_yn/venv/lib/python3.12/site-packages/fastapi/encoders.py", line 289, in jsonable_encoder
    encoded_value = jsonable_encoder(
                    ^^^^^^^^^^^^^^^^^
  File "/home/dj/projects/current/refined_yn/venv/lib/python3.12/site-packages/fastapi/encoders.py", line 303, in jsonable_encoder
    jsonable_encoder(
  File "/home/dj/projects/current/refined_yn/venv/lib/python3.12/site-packages/fastapi/encoders.py", line 289, in jsonable_encoder
    encoded_value = jsonable_encoder(
                    ^^^^^^^^^^^^^^^^^
  File "/home/dj/projects/current/refined_yn/venv/lib/python3.12/site-packages/fastapi/encoders.py", line 332, in jsonable_encoder
    raise ValueError(errors) from e
ValueError: [TypeError('cannot convert dictionary update sequence element #0 to a sequence'), TypeError('vars() argument must have __dict__ attribute')]
2025-04-19 09:37:46,868 - financial_prediction_system - ERROR - Unhandled exception: [TypeError('cannot convert dictionary update sequence element #0 to a sequence'), TypeError('vars() argument must have __dict__ attribute')]
Traceback (most recent call last):
  File "/home/dj/projects/current/refined_yn/venv/lib/python3.12/site-packages/fastapi/encoders.py", line 324, in jsonable_encoder
    data = dict(obj)
           ^^^^^^^^^
TypeError: cannot convert dictionary update sequence element #0 to a sequence

During handling of the above exception, another exception occurred:

Traceback (most recent call last):
  File "/home/dj/projects/current/refined_yn/venv/lib/python3.12/site-packages/fastapi/encoders.py", line 329, in jsonable_encoder
    data = vars(obj)
           ^^^^^^^^^
TypeError: vars() argument must have __dict__ attribute

The above exception was the direct cause of the following exception:

Traceback (most recent call last):
  File "/home/dj/projects/current/refined_yn/venv/lib/python3.12/site-packages/starlette/middleware/errors.py", line 165, in __call__
    await self.app(scope, receive, _send)
  File "/home/dj/projects/current/refined_yn/venv/lib/python3.12/site-packages/starlette/middleware/cors.py", line 85, in __call__
    await self.app(scope, receive, send)
  File "/home/dj/projects/current/refined_yn/venv/lib/python3.12/site-packages/starlette/middleware/exceptions.py", line 62, in __call__
    await wrap_app_handling_exceptions(self.app, conn)(scope, receive, send)
  File "/home/dj/projects/current/refined_yn/venv/lib/python3.12/site-packages/starlette/_exception_handler.py", line 53, in wrapped_app
    raise exc
  File "/home/dj/projects/current/refined_yn/venv/lib/python3.12/site-packages/starlette/_exception_handler.py", line 42, in wrapped_app
    await app(scope, receive, sender)
  File "/home/dj/projects/current/refined_yn/venv/lib/python3.12/site-packages/starlette/routing.py", line 714, in __call__
    await self.middleware_stack(scope, receive, send)
  File "/home/dj/projects/current/refined_yn/venv/lib/python3.12/site-packages/starlette/routing.py", line 734, in app
    await route.handle(scope, receive, send)
  File "/home/dj/projects/current/refined_yn/venv/lib/python3.12/site-packages/starlette/routing.py", line 288, in handle
    await self.app(scope, receive, send)
  File "/home/dj/projects/current/refined_yn/venv/lib/python3.12/site-packages/starlette/routing.py", line 76, in app
    await wrap_app_handling_exceptions(app, request)(scope, receive, send)
  File "/home/dj/projects/current/refined_yn/venv/lib/python3.12/site-packages/starlette/_exception_handler.py", line 53, in wrapped_app
    raise exc
  File "/home/dj/projects/current/refined_yn/venv/lib/python3.12/site-packages/starlette/_exception_handler.py", line 42, in wrapped_app
    await app(scope, receive, sender)
  File "/home/dj/projects/current/refined_yn/venv/lib/python3.12/site-packages/starlette/routing.py", line 73, in app
    response = await f(request)
               ^^^^^^^^^^^^^^^^
  File "/home/dj/projects/current/refined_yn/venv/lib/python3.12/site-packages/fastapi/routing.py", line 327, in app
    content = await serialize_response(
              ^^^^^^^^^^^^^^^^^^^^^^^^^
  File "/home/dj/projects/current/refined_yn/venv/lib/python3.12/site-packages/fastapi/routing.py", line 201, in serialize_response
    return jsonable_encoder(response_content)
           ^^^^^^^^^^^^^^^^^^^^^^^^^^^^^^^^^^
  File "/home/dj/projects/current/refined_yn/venv/lib/python3.12/site-packages/fastapi/encoders.py", line 289, in jsonable_encoder
    encoded_value = jsonable_encoder(
                    ^^^^^^^^^^^^^^^^^
  File "/home/dj/projects/current/refined_yn/venv/lib/python3.12/site-packages/fastapi/encoders.py", line 289, in jsonable_encoder
    encoded_value = jsonable_encoder(
                    ^^^^^^^^^^^^^^^^^
  File "/home/dj/projects/current/refined_yn/venv/lib/python3.12/site-packages/fastapi/encoders.py", line 303, in jsonable_encoder
    jsonable_encoder(
  File "/home/dj/projects/current/refined_yn/venv/lib/python3.12/site-packages/fastapi/encoders.py", line 289, in jsonable_encoder
    encoded_value = jsonable_encoder(
                    ^^^^^^^^^^^^^^^^^
  File "/home/dj/projects/current/refined_yn/venv/lib/python3.12/site-packages/fastapi/encoders.py", line 332, in jsonable_encoder
    raise ValueError(errors) from e
ValueError: [TypeError('cannot convert dictionary update sequence element #0 to a sequence'), TypeError('vars() argument must have __dict__ attribute')]
2025-04-19 09:40:52,238 - financial_prediction_system - ERROR - Unhandled exception: [TypeError('cannot convert dictionary update sequence element #0 to a sequence'), TypeError('vars() argument must have __dict__ attribute')]
Traceback (most recent call last):
  File "/home/dj/projects/current/refined_yn/venv/lib/python3.12/site-packages/fastapi/encoders.py", line 324, in jsonable_encoder
    data = dict(obj)
           ^^^^^^^^^
TypeError: cannot convert dictionary update sequence element #0 to a sequence

During handling of the above exception, another exception occurred:

Traceback (most recent call last):
  File "/home/dj/projects/current/refined_yn/venv/lib/python3.12/site-packages/fastapi/encoders.py", line 329, in jsonable_encoder
    data = vars(obj)
           ^^^^^^^^^
TypeError: vars() argument must have __dict__ attribute

The above exception was the direct cause of the following exception:

Traceback (most recent call last):
  File "/home/dj/projects/current/refined_yn/venv/lib/python3.12/site-packages/starlette/middleware/errors.py", line 165, in __call__
    await self.app(scope, receive, _send)
  File "/home/dj/projects/current/refined_yn/venv/lib/python3.12/site-packages/starlette/middleware/cors.py", line 85, in __call__
    await self.app(scope, receive, send)
  File "/home/dj/projects/current/refined_yn/venv/lib/python3.12/site-packages/starlette/middleware/exceptions.py", line 62, in __call__
    await wrap_app_handling_exceptions(self.app, conn)(scope, receive, send)
  File "/home/dj/projects/current/refined_yn/venv/lib/python3.12/site-packages/starlette/_exception_handler.py", line 53, in wrapped_app
    raise exc
  File "/home/dj/projects/current/refined_yn/venv/lib/python3.12/site-packages/starlette/_exception_handler.py", line 42, in wrapped_app
    await app(scope, receive, sender)
  File "/home/dj/projects/current/refined_yn/venv/lib/python3.12/site-packages/starlette/routing.py", line 714, in __call__
    await self.middleware_stack(scope, receive, send)
  File "/home/dj/projects/current/refined_yn/venv/lib/python3.12/site-packages/starlette/routing.py", line 734, in app
    await route.handle(scope, receive, send)
  File "/home/dj/projects/current/refined_yn/venv/lib/python3.12/site-packages/starlette/routing.py", line 288, in handle
    await self.app(scope, receive, send)
  File "/home/dj/projects/current/refined_yn/venv/lib/python3.12/site-packages/starlette/routing.py", line 76, in app
    await wrap_app_handling_exceptions(app, request)(scope, receive, send)
  File "/home/dj/projects/current/refined_yn/venv/lib/python3.12/site-packages/starlette/_exception_handler.py", line 53, in wrapped_app
    raise exc
  File "/home/dj/projects/current/refined_yn/venv/lib/python3.12/site-packages/starlette/_exception_handler.py", line 42, in wrapped_app
    await app(scope, receive, sender)
  File "/home/dj/projects/current/refined_yn/venv/lib/python3.12/site-packages/starlette/routing.py", line 73, in app
    response = await f(request)
               ^^^^^^^^^^^^^^^^
  File "/home/dj/projects/current/refined_yn/venv/lib/python3.12/site-packages/fastapi/routing.py", line 327, in app
    content = await serialize_response(
              ^^^^^^^^^^^^^^^^^^^^^^^^^
  File "/home/dj/projects/current/refined_yn/venv/lib/python3.12/site-packages/fastapi/routing.py", line 201, in serialize_response
    return jsonable_encoder(response_content)
           ^^^^^^^^^^^^^^^^^^^^^^^^^^^^^^^^^^
  File "/home/dj/projects/current/refined_yn/venv/lib/python3.12/site-packages/fastapi/encoders.py", line 289, in jsonable_encoder
    encoded_value = jsonable_encoder(
                    ^^^^^^^^^^^^^^^^^
  File "/home/dj/projects/current/refined_yn/venv/lib/python3.12/site-packages/fastapi/encoders.py", line 289, in jsonable_encoder
    encoded_value = jsonable_encoder(
                    ^^^^^^^^^^^^^^^^^
  File "/home/dj/projects/current/refined_yn/venv/lib/python3.12/site-packages/fastapi/encoders.py", line 303, in jsonable_encoder
    jsonable_encoder(
  File "/home/dj/projects/current/refined_yn/venv/lib/python3.12/site-packages/fastapi/encoders.py", line 289, in jsonable_encoder
    encoded_value = jsonable_encoder(
                    ^^^^^^^^^^^^^^^^^
  File "/home/dj/projects/current/refined_yn/venv/lib/python3.12/site-packages/fastapi/encoders.py", line 332, in jsonable_encoder
    raise ValueError(errors) from e
ValueError: [TypeError('cannot convert dictionary update sequence element #0 to a sequence'), TypeError('vars() argument must have __dict__ attribute')]
2025-04-19 09:40:52,284 - financial_prediction_system - ERROR - Unhandled exception: [TypeError('cannot convert dictionary update sequence element #0 to a sequence'), TypeError('vars() argument must have __dict__ attribute')]
Traceback (most recent call last):
  File "/home/dj/projects/current/refined_yn/venv/lib/python3.12/site-packages/fastapi/encoders.py", line 324, in jsonable_encoder
    data = dict(obj)
           ^^^^^^^^^
TypeError: cannot convert dictionary update sequence element #0 to a sequence

During handling of the above exception, another exception occurred:

Traceback (most recent call last):
  File "/home/dj/projects/current/refined_yn/venv/lib/python3.12/site-packages/fastapi/encoders.py", line 329, in jsonable_encoder
    data = vars(obj)
           ^^^^^^^^^
TypeError: vars() argument must have __dict__ attribute

The above exception was the direct cause of the following exception:

Traceback (most recent call last):
  File "/home/dj/projects/current/refined_yn/venv/lib/python3.12/site-packages/starlette/middleware/errors.py", line 165, in __call__
    await self.app(scope, receive, _send)
  File "/home/dj/projects/current/refined_yn/venv/lib/python3.12/site-packages/starlette/middleware/cors.py", line 85, in __call__
    await self.app(scope, receive, send)
  File "/home/dj/projects/current/refined_yn/venv/lib/python3.12/site-packages/starlette/middleware/exceptions.py", line 62, in __call__
    await wrap_app_handling_exceptions(self.app, conn)(scope, receive, send)
  File "/home/dj/projects/current/refined_yn/venv/lib/python3.12/site-packages/starlette/_exception_handler.py", line 53, in wrapped_app
    raise exc
  File "/home/dj/projects/current/refined_yn/venv/lib/python3.12/site-packages/starlette/_exception_handler.py", line 42, in wrapped_app
    await app(scope, receive, sender)
  File "/home/dj/projects/current/refined_yn/venv/lib/python3.12/site-packages/starlette/routing.py", line 714, in __call__
    await self.middleware_stack(scope, receive, send)
  File "/home/dj/projects/current/refined_yn/venv/lib/python3.12/site-packages/starlette/routing.py", line 734, in app
    await route.handle(scope, receive, send)
  File "/home/dj/projects/current/refined_yn/venv/lib/python3.12/site-packages/starlette/routing.py", line 288, in handle
    await self.app(scope, receive, send)
  File "/home/dj/projects/current/refined_yn/venv/lib/python3.12/site-packages/starlette/routing.py", line 76, in app
    await wrap_app_handling_exceptions(app, request)(scope, receive, send)
  File "/home/dj/projects/current/refined_yn/venv/lib/python3.12/site-packages/starlette/_exception_handler.py", line 53, in wrapped_app
    raise exc
  File "/home/dj/projects/current/refined_yn/venv/lib/python3.12/site-packages/starlette/_exception_handler.py", line 42, in wrapped_app
    await app(scope, receive, sender)
  File "/home/dj/projects/current/refined_yn/venv/lib/python3.12/site-packages/starlette/routing.py", line 73, in app
    response = await f(request)
               ^^^^^^^^^^^^^^^^
  File "/home/dj/projects/current/refined_yn/venv/lib/python3.12/site-packages/fastapi/routing.py", line 327, in app
    content = await serialize_response(
              ^^^^^^^^^^^^^^^^^^^^^^^^^
  File "/home/dj/projects/current/refined_yn/venv/lib/python3.12/site-packages/fastapi/routing.py", line 201, in serialize_response
    return jsonable_encoder(response_content)
           ^^^^^^^^^^^^^^^^^^^^^^^^^^^^^^^^^^
  File "/home/dj/projects/current/refined_yn/venv/lib/python3.12/site-packages/fastapi/encoders.py", line 289, in jsonable_encoder
    encoded_value = jsonable_encoder(
                    ^^^^^^^^^^^^^^^^^
  File "/home/dj/projects/current/refined_yn/venv/lib/python3.12/site-packages/fastapi/encoders.py", line 289, in jsonable_encoder
    encoded_value = jsonable_encoder(
                    ^^^^^^^^^^^^^^^^^
  File "/home/dj/projects/current/refined_yn/venv/lib/python3.12/site-packages/fastapi/encoders.py", line 303, in jsonable_encoder
    jsonable_encoder(
  File "/home/dj/projects/current/refined_yn/venv/lib/python3.12/site-packages/fastapi/encoders.py", line 289, in jsonable_encoder
    encoded_value = jsonable_encoder(
                    ^^^^^^^^^^^^^^^^^
  File "/home/dj/projects/current/refined_yn/venv/lib/python3.12/site-packages/fastapi/encoders.py", line 332, in jsonable_encoder
    raise ValueError(errors) from e
ValueError: [TypeError('cannot convert dictionary update sequence element #0 to a sequence'), TypeError('vars() argument must have __dict__ attribute')]
2025-04-19 09:41:01,910 - financial_prediction_system - ERROR - Unhandled exception: [TypeError('cannot convert dictionary update sequence element #0 to a sequence'), TypeError('vars() argument must have __dict__ attribute')]
Traceback (most recent call last):
  File "/home/dj/projects/current/refined_yn/venv/lib/python3.12/site-packages/fastapi/encoders.py", line 324, in jsonable_encoder
    data = dict(obj)
           ^^^^^^^^^
TypeError: cannot convert dictionary update sequence element #0 to a sequence

During handling of the above exception, another exception occurred:

Traceback (most recent call last):
  File "/home/dj/projects/current/refined_yn/venv/lib/python3.12/site-packages/fastapi/encoders.py", line 329, in jsonable_encoder
    data = vars(obj)
           ^^^^^^^^^
TypeError: vars() argument must have __dict__ attribute

The above exception was the direct cause of the following exception:

Traceback (most recent call last):
  File "/home/dj/projects/current/refined_yn/venv/lib/python3.12/site-packages/starlette/middleware/errors.py", line 165, in __call__
    await self.app(scope, receive, _send)
  File "/home/dj/projects/current/refined_yn/venv/lib/python3.12/site-packages/starlette/middleware/cors.py", line 85, in __call__
    await self.app(scope, receive, send)
  File "/home/dj/projects/current/refined_yn/venv/lib/python3.12/site-packages/starlette/middleware/exceptions.py", line 62, in __call__
    await wrap_app_handling_exceptions(self.app, conn)(scope, receive, send)
  File "/home/dj/projects/current/refined_yn/venv/lib/python3.12/site-packages/starlette/_exception_handler.py", line 53, in wrapped_app
    raise exc
  File "/home/dj/projects/current/refined_yn/venv/lib/python3.12/site-packages/starlette/_exception_handler.py", line 42, in wrapped_app
    await app(scope, receive, sender)
  File "/home/dj/projects/current/refined_yn/venv/lib/python3.12/site-packages/starlette/routing.py", line 714, in __call__
    await self.middleware_stack(scope, receive, send)
  File "/home/dj/projects/current/refined_yn/venv/lib/python3.12/site-packages/starlette/routing.py", line 734, in app
    await route.handle(scope, receive, send)
  File "/home/dj/projects/current/refined_yn/venv/lib/python3.12/site-packages/starlette/routing.py", line 288, in handle
    await self.app(scope, receive, send)
  File "/home/dj/projects/current/refined_yn/venv/lib/python3.12/site-packages/starlette/routing.py", line 76, in app
    await wrap_app_handling_exceptions(app, request)(scope, receive, send)
  File "/home/dj/projects/current/refined_yn/venv/lib/python3.12/site-packages/starlette/_exception_handler.py", line 53, in wrapped_app
    raise exc
  File "/home/dj/projects/current/refined_yn/venv/lib/python3.12/site-packages/starlette/_exception_handler.py", line 42, in wrapped_app
    await app(scope, receive, sender)
  File "/home/dj/projects/current/refined_yn/venv/lib/python3.12/site-packages/starlette/routing.py", line 73, in app
    response = await f(request)
               ^^^^^^^^^^^^^^^^
  File "/home/dj/projects/current/refined_yn/venv/lib/python3.12/site-packages/fastapi/routing.py", line 327, in app
    content = await serialize_response(
              ^^^^^^^^^^^^^^^^^^^^^^^^^
  File "/home/dj/projects/current/refined_yn/venv/lib/python3.12/site-packages/fastapi/routing.py", line 201, in serialize_response
    return jsonable_encoder(response_content)
           ^^^^^^^^^^^^^^^^^^^^^^^^^^^^^^^^^^
  File "/home/dj/projects/current/refined_yn/venv/lib/python3.12/site-packages/fastapi/encoders.py", line 289, in jsonable_encoder
    encoded_value = jsonable_encoder(
                    ^^^^^^^^^^^^^^^^^
  File "/home/dj/projects/current/refined_yn/venv/lib/python3.12/site-packages/fastapi/encoders.py", line 289, in jsonable_encoder
    encoded_value = jsonable_encoder(
                    ^^^^^^^^^^^^^^^^^
  File "/home/dj/projects/current/refined_yn/venv/lib/python3.12/site-packages/fastapi/encoders.py", line 303, in jsonable_encoder
    jsonable_encoder(
  File "/home/dj/projects/current/refined_yn/venv/lib/python3.12/site-packages/fastapi/encoders.py", line 289, in jsonable_encoder
    encoded_value = jsonable_encoder(
                    ^^^^^^^^^^^^^^^^^
  File "/home/dj/projects/current/refined_yn/venv/lib/python3.12/site-packages/fastapi/encoders.py", line 332, in jsonable_encoder
    raise ValueError(errors) from e
ValueError: [TypeError('cannot convert dictionary update sequence element #0 to a sequence'), TypeError('vars() argument must have __dict__ attribute')]
2025-04-19 09:41:01,944 - financial_prediction_system - ERROR - Unhandled exception: [TypeError('cannot convert dictionary update sequence element #0 to a sequence'), TypeError('vars() argument must have __dict__ attribute')]
Traceback (most recent call last):
  File "/home/dj/projects/current/refined_yn/venv/lib/python3.12/site-packages/fastapi/encoders.py", line 324, in jsonable_encoder
    data = dict(obj)
           ^^^^^^^^^
TypeError: cannot convert dictionary update sequence element #0 to a sequence

During handling of the above exception, another exception occurred:

Traceback (most recent call last):
  File "/home/dj/projects/current/refined_yn/venv/lib/python3.12/site-packages/fastapi/encoders.py", line 329, in jsonable_encoder
    data = vars(obj)
           ^^^^^^^^^
TypeError: vars() argument must have __dict__ attribute

The above exception was the direct cause of the following exception:

Traceback (most recent call last):
  File "/home/dj/projects/current/refined_yn/venv/lib/python3.12/site-packages/starlette/middleware/errors.py", line 165, in __call__
    await self.app(scope, receive, _send)
  File "/home/dj/projects/current/refined_yn/venv/lib/python3.12/site-packages/starlette/middleware/cors.py", line 85, in __call__
    await self.app(scope, receive, send)
  File "/home/dj/projects/current/refined_yn/venv/lib/python3.12/site-packages/starlette/middleware/exceptions.py", line 62, in __call__
    await wrap_app_handling_exceptions(self.app, conn)(scope, receive, send)
  File "/home/dj/projects/current/refined_yn/venv/lib/python3.12/site-packages/starlette/_exception_handler.py", line 53, in wrapped_app
    raise exc
  File "/home/dj/projects/current/refined_yn/venv/lib/python3.12/site-packages/starlette/_exception_handler.py", line 42, in wrapped_app
    await app(scope, receive, sender)
  File "/home/dj/projects/current/refined_yn/venv/lib/python3.12/site-packages/starlette/routing.py", line 714, in __call__
    await self.middleware_stack(scope, receive, send)
  File "/home/dj/projects/current/refined_yn/venv/lib/python3.12/site-packages/starlette/routing.py", line 734, in app
    await route.handle(scope, receive, send)
  File "/home/dj/projects/current/refined_yn/venv/lib/python3.12/site-packages/starlette/routing.py", line 288, in handle
    await self.app(scope, receive, send)
  File "/home/dj/projects/current/refined_yn/venv/lib/python3.12/site-packages/starlette/routing.py", line 76, in app
    await wrap_app_handling_exceptions(app, request)(scope, receive, send)
  File "/home/dj/projects/current/refined_yn/venv/lib/python3.12/site-packages/starlette/_exception_handler.py", line 53, in wrapped_app
    raise exc
  File "/home/dj/projects/current/refined_yn/venv/lib/python3.12/site-packages/starlette/_exception_handler.py", line 42, in wrapped_app
    await app(scope, receive, sender)
  File "/home/dj/projects/current/refined_yn/venv/lib/python3.12/site-packages/starlette/routing.py", line 73, in app
    response = await f(request)
               ^^^^^^^^^^^^^^^^
  File "/home/dj/projects/current/refined_yn/venv/lib/python3.12/site-packages/fastapi/routing.py", line 327, in app
    content = await serialize_response(
              ^^^^^^^^^^^^^^^^^^^^^^^^^
  File "/home/dj/projects/current/refined_yn/venv/lib/python3.12/site-packages/fastapi/routing.py", line 201, in serialize_response
    return jsonable_encoder(response_content)
           ^^^^^^^^^^^^^^^^^^^^^^^^^^^^^^^^^^
  File "/home/dj/projects/current/refined_yn/venv/lib/python3.12/site-packages/fastapi/encoders.py", line 289, in jsonable_encoder
    encoded_value = jsonable_encoder(
                    ^^^^^^^^^^^^^^^^^
  File "/home/dj/projects/current/refined_yn/venv/lib/python3.12/site-packages/fastapi/encoders.py", line 289, in jsonable_encoder
    encoded_value = jsonable_encoder(
                    ^^^^^^^^^^^^^^^^^
  File "/home/dj/projects/current/refined_yn/venv/lib/python3.12/site-packages/fastapi/encoders.py", line 303, in jsonable_encoder
    jsonable_encoder(
  File "/home/dj/projects/current/refined_yn/venv/lib/python3.12/site-packages/fastapi/encoders.py", line 289, in jsonable_encoder
    encoded_value = jsonable_encoder(
                    ^^^^^^^^^^^^^^^^^
  File "/home/dj/projects/current/refined_yn/venv/lib/python3.12/site-packages/fastapi/encoders.py", line 332, in jsonable_encoder
    raise ValueError(errors) from e
ValueError: [TypeError('cannot convert dictionary update sequence element #0 to a sequence'), TypeError('vars() argument must have __dict__ attribute')]
2025-04-19 09:42:39,892 - financial_prediction_system - INFO - Financial Prediction API shutting down
2025-04-19 09:42:42,193 - financial_prediction_system - INFO - Financial Prediction API starting up
2025-04-19 09:53:31,514 - financial_prediction_system - INFO - Financial Prediction API shutting down
2025-04-19 09:53:36,198 - financial_prediction_system - INFO - Financial Prediction API starting up
